[INFO  2019-09-09 05:05:57 @__init__.py:79] Set root logger. Unset logger with neuralgym.unset_logger().
[INFO  2019-09-09 05:05:57 @__init__.py:80] Saving logging to file: neuralgym_logs/20190909050557184379.
[INFO  2019-09-09 05:06:07 @_internal.py:122]  * Running on http://0.0.0.0:80/ (Press CTRL+C to quit)
[ERROR 2019-09-09 05:06:20 @app.py:1891] Exception on /insert [POST]
Traceback (most recent call last):
  File "C:\Users\Administrator\AppData\Local\Programs\Python\Python37\lib\site-packages\sqlalchemy\engine\base.py", line 1249, in _execute_context
    cursor, statement, parameters, context
  File "C:\Users\Administrator\AppData\Local\Programs\Python\Python37\lib\site-packages\sqlalchemy\engine\default.py", line 552, in do_execute
    cursor.execute(statement, parameters)
  File "C:\Users\Administrator\AppData\Local\Programs\Python\Python37\lib\site-packages\pymysql\cursors.py", line 170, in execute
    result = self._query(query)
  File "C:\Users\Administrator\AppData\Local\Programs\Python\Python37\lib\site-packages\pymysql\cursors.py", line 328, in _query
    conn.query(q)
  File "C:\Users\Administrator\AppData\Local\Programs\Python\Python37\lib\site-packages\pymysql\connections.py", line 517, in query
    self._affected_rows = self._read_query_result(unbuffered=unbuffered)
  File "C:\Users\Administrator\AppData\Local\Programs\Python\Python37\lib\site-packages\pymysql\connections.py", line 732, in _read_query_result
    result.read()
  File "C:\Users\Administrator\AppData\Local\Programs\Python\Python37\lib\site-packages\pymysql\connections.py", line 1075, in read
    first_packet = self.connection._read_packet()
  File "C:\Users\Administrator\AppData\Local\Programs\Python\Python37\lib\site-packages\pymysql\connections.py", line 684, in _read_packet
    packet.check_error()
  File "C:\Users\Administrator\AppData\Local\Programs\Python\Python37\lib\site-packages\pymysql\protocol.py", line 220, in check_error
    err.raise_mysql_exception(self._data)
  File "C:\Users\Administrator\AppData\Local\Programs\Python\Python37\lib\site-packages\pymysql\err.py", line 109, in raise_mysql_exception
    raise errorclass(errno, errval)
pymysql.err.DataError: (1406, "Data too long for column 'image' at row 1")

The above exception was the direct cause of the following exception:

Traceback (most recent call last):
  File "C:\Users\Administrator\AppData\Local\Programs\Python\Python37\lib\site-packages\flask\app.py", line 2446, in wsgi_app
    response = self.full_dispatch_request()
  File "C:\Users\Administrator\AppData\Local\Programs\Python\Python37\lib\site-packages\flask\app.py", line 1951, in full_dispatch_request
    rv = self.handle_user_exception(e)
  File "C:\Users\Administrator\AppData\Local\Programs\Python\Python37\lib\site-packages\flask\app.py", line 1820, in handle_user_exception
    reraise(exc_type, exc_value, tb)
  File "C:\Users\Administrator\AppData\Local\Programs\Python\Python37\lib\site-packages\flask\_compat.py", line 39, in reraise
    raise value
  File "C:\Users\Administrator\AppData\Local\Programs\Python\Python37\lib\site-packages\flask\app.py", line 1949, in full_dispatch_request
    rv = self.dispatch_request()
  File "C:\Users\Administrator\AppData\Local\Programs\Python\Python37\lib\site-packages\flask\app.py", line 1935, in dispatch_request
    return self.view_functions[rule.endpoint](**req.view_args)
  File "app.py", line 273, in InsertDB
    img_df.to_sql(name="imageinfo", con=engine, if_exists='append', index=False)
  File "C:\Users\Administrator\AppData\Local\Programs\Python\Python37\lib\site-packages\pandas\core\generic.py", line 2712, in to_sql
    method=method,
  File "C:\Users\Administrator\AppData\Local\Programs\Python\Python37\lib\site-packages\pandas\io\sql.py", line 518, in to_sql
    method=method,
  File "C:\Users\Administrator\AppData\Local\Programs\Python\Python37\lib\site-packages\pandas\io\sql.py", line 1320, in to_sql
    table.insert(chunksize, method=method)
  File "C:\Users\Administrator\AppData\Local\Programs\Python\Python37\lib\site-packages\pandas\io\sql.py", line 756, in insert
    exec_insert(conn, keys, chunk_iter)
  File "C:\Users\Administrator\AppData\Local\Programs\Python\Python37\lib\site-packages\pandas\io\sql.py", line 670, in _execute_insert
    conn.execute(self.table.insert(), data)
  File "C:\Users\Administrator\AppData\Local\Programs\Python\Python37\lib\site-packages\sqlalchemy\engine\base.py", line 988, in execute
    return meth(self, multiparams, params)
  File "C:\Users\Administrator\AppData\Local\Programs\Python\Python37\lib\site-packages\sqlalchemy\sql\elements.py", line 287, in _execute_on_connection
    return connection._execute_clauseelement(self, multiparams, params)
  File "C:\Users\Administrator\AppData\Local\Programs\Python\Python37\lib\site-packages\sqlalchemy\engine\base.py", line 1107, in _execute_clauseelement
    distilled_params,
  File "C:\Users\Administrator\AppData\Local\Programs\Python\Python37\lib\site-packages\sqlalchemy\engine\base.py", line 1253, in _execute_context
    e, statement, parameters, cursor, context
  File "C:\Users\Administrator\AppData\Local\Programs\Python\Python37\lib\site-packages\sqlalchemy\engine\base.py", line 1473, in _handle_dbapi_exception
    util.raise_from_cause(sqlalchemy_exception, exc_info)
  File "C:\Users\Administrator\AppData\Local\Programs\Python\Python37\lib\site-packages\sqlalchemy\util\compat.py", line 398, in raise_from_cause
    reraise(type(exception), exception, tb=exc_tb, cause=cause)
  File "C:\Users\Administrator\AppData\Local\Programs\Python\Python37\lib\site-packages\sqlalchemy\util\compat.py", line 152, in reraise
    raise value.with_traceback(tb)
  File "C:\Users\Administrator\AppData\Local\Programs\Python\Python37\lib\site-packages\sqlalchemy\engine\base.py", line 1249, in _execute_context
    cursor, statement, parameters, context
  File "C:\Users\Administrator\AppData\Local\Programs\Python\Python37\lib\site-packages\sqlalchemy\engine\default.py", line 552, in do_execute
    cursor.execute(statement, parameters)
  File "C:\Users\Administrator\AppData\Local\Programs\Python\Python37\lib\site-packages\pymysql\cursors.py", line 170, in execute
    result = self._query(query)
  File "C:\Users\Administrator\AppData\Local\Programs\Python\Python37\lib\site-packages\pymysql\cursors.py", line 328, in _query
    conn.query(q)
  File "C:\Users\Administrator\AppData\Local\Programs\Python\Python37\lib\site-packages\pymysql\connections.py", line 517, in query
    self._affected_rows = self._read_query_result(unbuffered=unbuffered)
  File "C:\Users\Administrator\AppData\Local\Programs\Python\Python37\lib\site-packages\pymysql\connections.py", line 732, in _read_query_result
    result.read()
  File "C:\Users\Administrator\AppData\Local\Programs\Python\Python37\lib\site-packages\pymysql\connections.py", line 1075, in read
    first_packet = self.connection._read_packet()
  File "C:\Users\Administrator\AppData\Local\Programs\Python\Python37\lib\site-packages\pymysql\connections.py", line 684, in _read_packet
    packet.check_error()
  File "C:\Users\Administrator\AppData\Local\Programs\Python\Python37\lib\site-packages\pymysql\protocol.py", line 220, in check_error
    err.raise_mysql_exception(self._data)
  File "C:\Users\Administrator\AppData\Local\Programs\Python\Python37\lib\site-packages\pymysql\err.py", line 109, in raise_mysql_exception
    raise errorclass(errno, errval)
sqlalchemy.exc.DataError: (pymysql.err.DataError) (1406, "Data too long for column 'image' at row 1")
[SQL: INSERT INTO imageinfo (image) VALUES (%(image)s)]
[parameters: {'image': b'/9j/4AAQSkZJRgABAQAAAQABAAD/2wBDAAgGBgcGBQgHBwcJCQgKDBQNDAsLDBkSEw8UHRofHh0aHBwgJC4nICIsIxwcKDcpLDAxNDQ0Hyc5PTgyPC4zNDL/2wBDAQkJCQwLDBgNDRgyIRwhMjIy ... (78971 characters truncated) ... RQBmWs5spfJk/1LHg/wB0/wCFamRVW7tlmQkDmoLG5MbfZpj/ALhP8qYI0RzTT1p9M6mkA3vQOlLxSEUAAHFKOlA+7Sds0AKCQakU5qKlDYNADmiwMr09Kj7VYR6ZJH/Ev4igCJT2oNHeg0Af/9k='}]
(Background on this error at: http://sqlalche.me/e/9h9h)
[INFO  2019-09-09 05:06:20 @_internal.py:122] 180.71.27.249 - - [09/Sep/2019 05:06:20] "[1m[35mPOST /insert HTTP/1.1[0m" 500 -
